Traceback (most recent call last):
  File "train_surface3d.py", line 155, in <module>
    main()
  File "train_surface3d.py", line 110, in main
    for x in trainloader:
  File "/zhome/77/8/118225/.local/lib/python3.8/site-packages/torch/utils/data/dataloader.py", line 435, in __next__
    data = self._next_data()
  File "/zhome/77/8/118225/.local/lib/python3.8/site-packages/torch/utils/data/dataloader.py", line 1085, in _next_data
    return self._process_data(data)
  File "/zhome/77/8/118225/.local/lib/python3.8/site-packages/torch/utils/data/dataloader.py", line 1111, in _process_data
    data.reraise()
  File "/zhome/77/8/118225/.local/lib/python3.8/site-packages/torch/_utils.py", line 428, in reraise
    raise self.exc_type(msg)
RuntimeError: Caught RuntimeError in DataLoader worker process 0.
Original Traceback (most recent call last):
  File "/zhome/77/8/118225/.local/lib/python3.8/site-packages/torch/utils/data/_utils/worker.py", line 198, in _worker_loop
    data = fetcher.fetch(index)
  File "/zhome/77/8/118225/.local/lib/python3.8/site-packages/torch/utils/data/_utils/fetch.py", line 44, in fetch
    data = [self.dataset[idx] for idx in possibly_batched_index]
  File "/zhome/77/8/118225/.local/lib/python3.8/site-packages/torch/utils/data/_utils/fetch.py", line 44, in <listcomp>
    data = [self.dataset[idx] for idx in possibly_batched_index]
RuntimeError: CUDA error: initialization error

